Workbook

Sheet Data all
A1: DisNo. | B1: Disaster Subgroup | C1: Disaster Type | D1: Disaster Subtype | E1: Start Year | F1: Total Damage ('000 US$) | G1: External IDs | H1: ISO | I1: Country | J1: Location | K1: Origin | L1: Associated Types | M1: OFDA/BHA Response | N1: Appeal | O1: Declaration | P1: AID Contribution ('000 US$) | Q1: Magnitude | R1: Latitude | S1: Longitude | T1: River Basin
A2: 2000-0465-USA | B2: Climatological | C2: Wildfire | D2: Forest fire | E2: 2000 | F2: 1000000 | H2: USA | I2: United States of America | J2: Arizona, California, Colorado, Idaho, Montana, Nevada, New Mexico, Oregon, South Dakota, Texas, Utah, Washington, Wyoming, Florida, North Dakota provinces | M2: No | N2: No | O2: No | Q2: 680000
A3: 2000-0265-COL | B3: Hydrological | C3: Flood | D3: Riverine flood | E3: 2000 | H3: COL | I3: Colombia | J3: Narino, Putumayo, Santander, Antioquia, Choco, Cundinamarca, Tolima, Valle del Cauca, Amazonas provinces | K3: Heavy rains | L3: Slide (land, mud, snow, rock)|Transport accident | M3: No | N3: No | O3: No | P3: 9 | Q3: 200000 | T3: San Miguel
A4: 2000-0271-USA | B4: Hydrological | C4: Flood | D4: Flash flood | E4: 2000 | H4: USA | I4: United States of America | J4: Oklahoma province | K4: Brief torrential rain | M4: No | N4: No | O4: No | T4: Polecat Creek, Bird Creek, Neosho River, and Caney River
A5: 2000-0450-USA | B5: Climatological | C5: Wildfire | D5: Forest fire | E5: 2000 | H5: USA | I5: United States of America | J5: Alaska province | M5: No | N5: No | O5: No | Q5: 2363
A6: 2000-0466-BRA | B6: Hydrological | C6: Mass movement (wet) | D6: Mudslide | E6: 2000 | F6: 75000 | H6: BRA | I6: Brazil | J6: Alagoas, Pernambuco provinces | M6: No | N6: No | O6: No
A7: 2000-0502-USA | B7: Hydrological | C7: Flood | D7: Flood (General) | E7: 2000 | H7: USA | I7: United States of America | J7: Pennsylvania province | M7: No | N7: No | O7: No
A8: 2000-0853-ARG | B8: Climatological | C8: Wildfire | D8: Forest fire | E8: 2000 | H8: ARG | I8: Argentina | J8: La Pampa, Mendoza, San Luis, Formosa provinces | M8: No | N8: No | O8: No | Q8: 20500
A9: 2000-0865-USA | B9: Hydrological | C9: Flood | D9: Riverine flood | E9: 2000 | F9: 20000 | H9: USA | I9: United States of America | J9: Maui district (Hawaii province) | K9: Heavy rains | M9: No | N9: No | O9: No | Q9: 86
A10: 2000-0067-USA | B10: Meteorological | C10: Storm | D10: Tornado | E10: 2000 | H10: USA | I10: United States of America | J10: Bullock, Montgomery districts (Alabama province), Colquitt, Grady, Mitchell, Thomas, Tift districts (Georgia province), Washington district (Floride province), Lonoke, Prairie, Saline districts (Arkansas province) | M10: No | N10: No | O10: No | Q10: 249
A11: 2000-0098-COL | B11: Hydrological | C11: Flood | D11: Flood (General) | E11: 2000 | H11: COL | I11: Colombia | J11: Tolima, Santander, Valle provinces | M11: No | N11: No | O11: No
A12: 2000-0116-ARG | B12: Hydrological | C12: Flood | D12: Riverine flood | E12: 2000 | H12: ARG | I12: Argentina | J12: Catamarca, Cordoba, Jujuy, La Rioja, Santiago del Estero, Salta,Tucuman provinces | K12: Heavy rain | M12: No | N12: No | O12: No
A13: 2000-0204-ECU | B13: Biological | C13: Epidemic | D13: Parasitic disease | E13: 2000 | H13: ECU | I13: Ecuador | J13: Guayas, Los Rios provinces | M13: No | N13: No | O13: No
A14: 2000-0206-ECU | B14: Hydrological | C14: Mass movement (wet) | D14: Landslide (wet) | E14: 2000 | H14: ECU | I14: Ecuador | J14: Quito district (Pichincha province) | M14: No | N14: No | O14: No
A15: 2000-0130-BOL | B15: Hydrological | C15: Flood | D15: Riverine flood | E15: 2000 | H15: BOL | I15: Bolivia (Plurinational State of) | J15: Nuflo de Chavez, Obispo Santiesteban districts (Santa Cruz province), Bermejo town (Acre district, Tarija province), Avilez district (Tarija province), Gran Chaco district (Tarija province), Chuquisaca province | K15: Heavy rains | M15: No | N15: No | O15: No | Q15: 750 | T15: Bermejo, Grande
A16: 2000-0317-MEX | B16: Hydrological | C16: Flood | D16: Flood (General) | E16: 2000 | H16: MEX | I16: Mexico | J16: Chalco district (Mexico province) | M16: No | N16: No | O16: No
A17: 2000-0333-MEX | B17: Hydrological | C17: Flood | D17: Flood (General) | E17: 2000 | H17: MEX | I17: Mexico | J17: Acatlan de Perez Figueroa city (Tuxtepec district, Oaxaca province) | L17: Slide (land, mud, snow, rock) | M17: No | N17: No | O17: No
A18: 2000-0345-NIC | B18: Hydrological | C18: Flood | D18: Riverine flood | E18: 2000 | H18: NIC | I18: Nicaragua | J18: El Rama district (Atlantico Sur province) | M18: No | N18: No | O18: No
A19: 2000-0363-USA | B19: Climatological | C19: Wildfire | D19: Forest fire | E19: 2000 | H19: USA | I19: United States of America | J19: Park, Jefferson, Larimer districts (Colorado province) | M19: No | N19: No | O19: No | Q19: 85
A20: 2000-0586-PER | B20: Hydrological | C20: Mass movement (wet) | D20: Landslide (wet) | E20: 2000 | H20: PER | I20: Peru | J20: Arma village (La Convenci?n district, Cusco province) | M20: No | N20: No | O20: No
A21: 2000-0645-SLV | B21: Meteorological | C21: Storm | D21: Tropical cyclone | E21: 2000 | H21: SLV | I21: El Salvador | J21: Ahuachapan, Cabanas, Chalatenango, Cuscatlan, La Libertad, La Paz, La Union, Morazan, San Miguel, San Salvador, San Vicente, Santa Ana, Sonsonate, Usulutan provinces | M21: No | N21: No | O21: No
A22: 2000-0652-USA | B22: Meteorological | C22: Storm | D22: Tropical cyclone | E22: 2000 | F22: 219000 | H22: USA | I22: United States of America | J22: Miami-Dade, Monroe, Broward, Collier districts (Florida province) | M22: No | N22: No | O22: No
A23: 2000-0724-ECU | B23: Hydrological | C23: Mass movement (wet) | D23: Mudslide | E23: 2000 | H23: ECU | I23: Ecuador | J23: Penipe, Guano districts (Chimborazo province) | M23: No | N23: No | O23: No
A24: 2000-0839-ARG | B24: Meteorological | C24: Storm | D24: Lightning/Thunderstorms | E24: 2000 | H24: ARG | I24: Argentina | J24: Buenos Aires D.f., Buenos Aires provinces | M24: No | N24: No | O24: No | Q24: 96
A25: 2000-0827-MEX | B25: Meteorological | C25: Extreme temperature | D25: Cold wave | E25: 2000 | H25: MEX | I25: Mexico | J25: Chihuahua province | M25: No | N25: No | O25: No
A26: 2000-0905-BOL | B26: Hydrological | C26: Flood | D26: Flood (General) | E26: 2000 | H26: BOL | I26: Bolivia (Plurinational State of) | J26: Chuquisaca, Cochabamba, La Paz, Oruro, Potosi, Tarija provinces | L26: Slide (land, mud, snow, rock) | M26: No | N26: No | O26: No
A27: 2000-0919-USA | B27: Meteorological | C27: Storm | D27: Storm (General) | E27: 2000 | F27: 350000 | H27: USA | I27: United States of America | J27: Alabama, Georgia, Louisiana, North Carolina, South Carolina, Tennessee, Virginia, New York, Pennsylvania, Massachussetts provinces | L27: Cold wave | M27: No | N27: No | O27: No
A28: 2000-0937-USA | B28: Meteorological | C28: Storm | D28: Storm (General) | E28: 2000 | F28: 500000 | H28: USA | I28: United States of America | J28: Tuscaloosa district (Alabama province), Connecticut, Florida, Georgia, Massachusetts, Mississippi, Norh Carolina, New Jersey, New York, Pennsylvania, Rhode Island provinces | M28: No | N28: No | O28: No
A29: 2000-9339-USA | B29: Climatological | C29: Drought | D29: Drought | E29: 2000 | F29: 1100000 | H29: USA | I29: United States of America | J29: South Carolina, Georgia, Alabama, Florida, Louisiana, Texas provinces | M29: No | N29: No | O29: Yes
A30: 2000-9860-NIC | B30: Climatological | C30: Drought | D30: Drought | E30: 2000 | H30: NIC | I30: Nicaragua | J30: Atlantico Norte, Jinotega, Nueva Segovia provinces | L30: Famine | M30: No | N30: No | O30: No
A31: 2000-0128-USA | B31: Climatological | C31: Wildfire | D31: Forest fire | E31: 2000 | H31: USA | I31: United States of America | J31: Gainesville, Alachua areas (Alachua district, Florida province), Lafayette, Gulf districts (Florida province) | M31: No | N31: No | O31: No | Q31: 113
A32: 2000-0266-ECU | B32: Hydrological | C32: Flood | D32: Flood (General) | E32: 2000 | H32: ECU | I32: Ecuador | J32: Carchi, Imbabura provinces | M32: No | N32: No | O32: No
A33: 2000-0338-USA | B33: Meteorological | C33: Storm | D33: Tornado | E33: 2000 | F33: 28500 | H33: USA | I33: United States of America | J33: Adams, Columbia, Crawford, Dane, Dodge, Grant, Green, Iowa, Juneau, La crosse, Lafayette, Monroe, Richland, Rock, Sauk, Vernon districts (Wisconsin province) | M33: No | N33: No | O33: No
A34: 2000-0374-CRI | B34: Hydrological | C34: Mass movement (wet) | D34: Landslide (wet) | E34: 2000 | H34: CRI | I34: Costa Rica | J34: Miramar de Puntarenas town (Montes de Oro district, Puntarenas province) | M34: No | N34: No | O34: No
A35: 2000-0387-NIC | B35: Geophysical | C35: Earthquake | D35: Ground movement | E35: 2000 | G35: USGS:usp0009vy1 | H35: NIC | I35: Nicaragua | J35: Laguna de Apoyo nature reserve (Masaya district, Masaya province) | M35: No | N35: No | O35: No | P35: 69 | Q35: 5.4 | R35: 11.884 | S35: -85.988
A36: 2000-0406-USA | B36: Climatological | C36: Wildfire | D36: Forest fire | E36: 2000 | H36: USA | I36: United States of America | J36: Hanford area (Benton district, Washington province) | M36: No | N36: No | O36: No | Q36: 607
A37: 2000-0421-ARG | B37: Meteorological | C37: Extreme temperature | D37: Cold wave | E37: 2000 | H37: ARG | I37: Argentina | J37: Buenos Aires, Sante Fe, Formosa, Santa Cruz provinces | M37: No | N37: No | O37: No | Q37: 0
A38: 2000-0423-CHL | B38: Meteorological | C38: Extreme temperature | D38: Cold wave | E38: 2000 | F38: 10000 | H38: CHL | I38: Chile | J38: Antofagasta, Araucania, Arica y Painacota, Atacama, Coquimbo, Los Lagos, Los Rios, Tarapaca provinces | M38: No | N38: No | O38: No | Q38: -20
A39: 2000-0433-USA | B39: Meteorological | C39: Extreme temperature | D39: Heat wave | E39: 2000 | H39: USA | I39: United States of America | J39: Texas, Louisiana, Alabama provinces | M39: No | N39: No | O39: No | Q39: 38
A40: 2000-0595-SLV | B40: Hydrological | C40: Flood | D40: Riverine flood | E40: 2000 | H40: SLV | I40: El Salvador | J40: Cabanas, Cuscatlan, La Paz, La Union, Morazan, San Miguel, San Salvador, San Vicente, Usulutan provinces | K40: Heavy rain | M40: No | N40: No | O40: Yes
...

Sheet EM-DAT Data
A1: DisNo. | B1: Disaster Subgroup | C1: Disaster Subtype | D1: Start Year | E1: Total Damage ('000 US$) | F1: Country | G1: Associated Types | H1: OFDA/BHA Response | I1: Appeal | J1: Declaration | K1: Total Affected | L1: Total Damage, Adjusted ('000 US$) | M1: CPI
A2: 2000-0465-USA | B2: Climatological | C2: Forest fire | D2: 2000 | E2: 1000000 | F2: United States of America | H2: No | I2: No | J2: No | K2: 1000 | L2: 1869587 | M2: 53.487737
A3: 2000-0265-COL | B3: Hydrological | C3: Riverine flood | D3: 2000 | F3: Colombia | G3: Slide (land, mud, snow, rock)|Transport accident | H3: No | I3: No | J3: No | K3: 12000 | M3: 53.487737
A4: 2000-0271-USA | B4: Hydrological | C4: Flash flood | D4: 2000 | F4: United States of America | H4: No | I4: No | J4: No | K4: 300 | M4: 53.487737
A5: 2000-0450-USA | B5: Climatological | C5: Forest fire | D5: 2000 | F5: United States of America | H5: No | I5: No | J5: No | M5: 53.487737
A6: 2000-0466-BRA | B6: Hydrological | C6: Mudslide | D6: 2000 | E6: 75000 | F6: Brazil | H6: No | I6: No | J6: No | K6: 143000 | L6: 140219 | M6: 53.487737
A7: 2000-0502-USA | B7: Hydrological | C7: Flood (General) | D7: 2000 | F7: United States of America | H7: No | I7: No | J7: No | K7: 300 | M7: 53.487737
A8: 2000-0853-ARG | B8: Climatological | C8: Forest fire | D8: 2000 | F8: Argentina | H8: No | I8: No | J8: No | M8: 53.487737
A9: 2000-0865-USA | B9: Hydrological | C9: Riverine flood | D9: 2000 | E9: 20000 | F9: United States of America | H9: No | I9: No | J9: No | K9: 100 | L9: 37392 | M9: 53.487737
A10: 2000-0067-USA | B10: Meteorological | C10: Tornado | D10: 2000 | F10: United States of America | H10: No | I10: No | J10: No | K10: 1000 | M10: 53.487737
A11: 2000-0098-COL | B11: Hydrological | C11: Flood (General) | D11: 2000 | F11: Colombia | H11: No | I11: No | J11: No | K11: 39000 | M11: 53.487737
A12: 2000-0116-ARG | B12: Hydrological | C12: Riverine flood | D12: 2000 | F12: Argentina | H12: No | I12: No | J12: No | K12: 6000 | M12: 53.487737
A13: 2000-0204-ECU | B13: Biological | C13: Parasitic disease | D13: 2000 | F13: Ecuador | H13: No | I13: No | J13: No | K13: 100000 | M13: 53.487737
A14: 2000-0206-ECU | B14: Hydrological | C14: Landslide (wet) | D14: 2000 | F14: Ecuador | H14: No | I14: No | J14: No | K14: 205 | M14: 53.487737
A15: 2000-0130-BOL | B15: Hydrological | C15: Riverine flood | D15: 2000 | F15: Bolivia (Plurinational State of) | H15: No | I15: No | J15: No | K15: 7000 | M15: 53.487737
A16: 2000-0317-MEX | B16: Hydrological | C16: Flood (General) | D16: 2000 | F16: Mexico | H16: No | I16: No | J16: No | K16: 2000 | M16: 53.487737
A17: 2000-0333-MEX | B17: Hydrological | C17: Flood (General) | D17: 2000 | F17: Mexico | G17: Slide (land, mud, snow, rock) | H17: No | I17: No | J17: No | M17: 53.487737
A18: 2000-0345-NIC | B18: Hydrological | C18: Riverine flood | D18: 2000 | F18: Nicaragua | H18: No | I18: No | J18: No | K18: 5500 | M18: 53.487737
A19: 2000-0363-USA | B19: Climatological | C19: Forest fire | D19: 2000 | F19: United States of America | H19: No | I19: No | J19: No | K19: 1010 | M19: 53.487737
A20: 2000-0586-PER | B20: Hydrological | C20: Landslide (wet) | D20: 2000 | F20: Peru | H20: No | I20: No | J20: No | M20: 53.487737
A21: 2000-0645-SLV | B21: Meteorological | C21: Tropical cyclone | D21: 2000 | F21: El Salvador | H21: No | I21: No | J21: No | K21: 100 | M21: 53.487737
A22: 2000-0652-USA | B22: Meteorological | C22: Tropical cyclone | D22: 2000 | E22: 219000 | F22: United States of America | H22: No | I22: No | J22: No | K22: 17433 | L22: 409440 | M22: 53.487737
A23: 2000-0724-ECU | B23: Hydrological | C23: Mudslide | D23: 2000 | F23: Ecuador | H23: No | I23: No | J23: No | K23: 180 | M23: 53.487737
A24: 2000-0839-ARG | B24: Meteorological | C24: Lightning/Thunderstorms | D24: 2000 | F24: Argentina | H24: No | I24: No | J24: No | K24: 430 | M24: 53.487737
A25: 2000-0827-MEX | B25: Meteorological | C25: Cold wave | D25: 2000 | F25: Mexico | H25: No | I25: No | J25: No | M25: 53.487737
A26: 2000-0905-BOL | B26: Hydrological | C26: Flood (General) | D26: 2000 | F26: Bolivia (Plurinational State of) | G26: Slide (land, mud, snow, rock) | H26: No | I26: No | J26: No | K26: 10 | M26: 53.487737
A27: 2000-0919-USA | B27: Meteorological | C27: Storm (General) | D27: 2000 | E27: 350000 | F27: United States of America | G27: Cold wave | H27: No | I27: No | J27: No | L27: 654356 | M27: 53.487737
A28: 2000-0937-USA | B28: Meteorological | C28: Storm (General) | D28: 2000 | E28: 500000 | F28: United States of America | H28: No | I28: No | J28: No | K28: 75 | L28: 934794 | M28: 53.487737
A29: 2000-9339-USA | B29: Climatological | C29: Drought | D29: 2000 | E29: 1100000 | F29: United States of America | H29: No | I29: No | J29: Yes | L29: 2056546 | M29: 53.487737
A30: 2000-9860-NIC | B30: Climatological | C30: Drought | D30: 2000 | F30: Nicaragua | G30: Famine | H30: No | I30: No | J30: No | M30: 53.487737
A31: 2000-0128-USA | B31: Climatological | C31: Forest fire | D31: 2000 | F31: United States of America | H31: No | I31: No | J31: No | K31: 600 | M31: 53.487737
A32: 2000-0266-ECU | B32: Hydrological | C32: Flood (General) | D32: 2000 | F32: Ecuador | H32: No | I32: No | J32: No | K32: 32 | M32: 53.487737
A33: 2000-0338-USA | B33: Meteorological | C33: Tornado | D33: 2000 | E33: 28500 | F33: United States of America | H33: No | I33: No | J33: No | L33: 53283 | M33: 53.487737
A34: 2000-0374-CRI | B34: Hydrological | C34: Landslide (wet) | D34: 2000 | F34: Costa Rica | H34: No | I34: No | J34: No | K34: 200 | M34: 53.487737
A35: 2000-0387-NIC | B35: Geophysical | C35: Ground movement | D35: 2000 | F35: Nicaragua | H35: No | I35: No | J35: No | K35: 7477 | M35: 53.487737
A36: 2000-0406-USA | B36: Climatological | C36: Forest fire | D36: 2000 | F36: United States of America | H36: No | I36: No | J36: No | K36: 8077 | M36: 53.487737
A37: 2000-0421-ARG | B37: Meteorological | C37: Cold wave | D37: 2000 | F37: Argentina | H37: No | I37: No | J37: No | K37: 300 | M37: 53.487737
A38: 2000-0423-CHL | B38: Meteorological | C38: Cold wave | D38: 2000 | E38: 10000 | F38: Chile | H38: No | I38: No | J38: No | L38: 18696 | M38: 53.487737
A39: 2000-0433-USA | B39: Meteorological | C39: Heat wave | D39: 2000 | F39: United States of America | H39: No | I39: No | J39: No | M39: 53.487737
A40: 2000-0595-SLV | B40: Hydrological | C40: Riverine flood | D40: 2000 | F40: El Salvador | H40: No | I40: No | J40: Yes | K40: 400 | M40: 53.487737
...

Sheet GDP
A1: Year | B1: GDP (current US$) | C1: Normalized Damage (xt) | D1: Keep
A2: 2000 | B2: 6.5544819e+11 | C2: 0 | D2: =IF(C2>=0.00001,"Yes","No") -> No
A3: 2001 | B3: 5.599837e+11 | C3: =('EM-DAT Data'!E314*1000)/GDP!B3 -> 8.0359481e-05 | D3: =IF(C3>=0.00001,"Yes","No") -> Yes
A4: 2002 | B4: 5.0979527e+11 | C4: 0 | D4: =IF(C4>=0.00001,"Yes","No") -> No
A5: 2003 | B5: 5.5823372e+11 | C5: =('EM-DAT Data'!E459*1000)/GDP!B5 -> 0.0005427834 | D5: =IF(C5>=0.00001,"Yes","No") -> Yes
A6: 2004 | B6: 6.6928932e+11 | C6: =('EM-DAT Data'!E707*1000)/GDP!B6 -> 5.528252e-07 | D6: =IF(C6>=0.00001,"Yes","No") -> No
A7: 2005 | B7: 8.9163383e+11 | C7: 0 | D7: =IF(C7>=0.00001,"Yes","No") -> No
A8: 2006 | B8: 1.1076267e+12 | C8: 0 | D8: =IF(C8>=0.00001,"Yes","No") -> No
A9: 2007 | B9: 1.3971142e+12 | C9: =('EM-DAT Data'!E788*1000)/GDP!B9 -> 8.9470135e-05 | D9: =IF(C9>=0.00001,"Yes","No") -> Yes
A10: 2008 | B10: 1.6958554e+12 | C10: =('EM-DAT Data'!E887*1000)/GDP!B10 -> 0.00065453694 | D10: =IF(C10>=0.00001,"Yes","No") -> Yes
A11: 2009 | B11: 1.6669963e+12 | C11: =('EM-DAT Data'!E984*1000)/GDP!B11 -> 0.00035992881 | D11: =IF(C11>=0.00001,"Yes","No") -> Yes
A12: 2010 | B12: 2.2088381e+12 | C12: =('EM-DAT Data'!E1055*1000)/GDP!B12 -> 0.00036308682 | D12: =IF(C12>=0.00001,"Yes","No") -> Yes
A13: 2011 | B13: 2.6161566e+12 | C13: =('EM-DAT Data'!E1171*1000)/GDP!B13 -> 0.00038300459 | D13: =IF(C13>=0.00001,"Yes","No") -> Yes
A14: 2012 | B14: 2.4652283e+12 | C14: =('EM-DAT Data'!E1254*1000)/GDP!B14 -> 6.9364773e-05 | D14: =IF(C14>=0.00001,"Yes","No") -> Yes
A15: 2013 | B15: 2.4728194e+12 | C15: =('EM-DAT Data'!E1356*1000)/GDP!B15 -> 0.0002205984 | D15: =IF(C15>=0.00001,"Yes","No") -> Yes
A16: 2014 | B16: 2.4560438e+12 | C16: =('EM-DAT Data'!E1462*1000)/GDP!B16 -> 8.1431774e-05 | D16: =IF(C16>=0.00001,"Yes","No") -> Yes
A17: 2015 | B17: 1.802212e+12 | C17: =('EM-DAT Data'!E1513*1000)/GDP!B17 -> 1.1097474e-06 | D17: =IF(C17>=0.00001,"Yes","No") -> No
A18: 2016 | B18: 1.7956933e+12 | C18: =('EM-DAT Data'!E1612*1000)/GDP!B18 -> 0.0001113776 | D18: =IF(C18>=0.00001,"Yes","No") -> Yes
A19: 2017 | B19: 2.0635147e+12 | C19: =('EM-DAT Data'!E1694*1000)/GDP!B19 -> 4.8461007e-05 | D19: =IF(C19>=0.00001,"Yes","No") -> Yes
A20: 2018 | B20: 1.9169337e+12 | C20: =('EM-DAT Data'!E1881*1000)/GDP!B20 -> 2.7648322e-05 | D20: =IF(C20>=0.00001,"Yes","No") -> Yes
A21: 2019 | B21: 1.8732882e+12 | C21: 0 | D21: =IF(C21>=0.00001,"Yes","No") -> No
A22: 2020 | B22: 1.4761073e+12 | C22: =('EM-DAT Data'!E1963*1000)/GDP!B22 -> 0.00033872876 | D22: =IF(C22>=0.00001,"Yes","No") -> Yes
A23: 2021 | B23: 1.6706475e+12 | C23: =('EM-DAT Data'!E2090*1000)/GDP!B23 -> 0.00032502369 | D23: =IF(C23>=0.00001,"Yes","No") -> Yes
A24: 2022 | B24: 1.9519238e+12 | C24: =('EM-DAT Data'!E2188*1000)/GDP!B24 -> 0.0005845515 | D24: =IF(C24>=0.00001,"Yes","No") -> Yes
A25: 2023 | B25: 2.1911319e+12 | C25: =('EM-DAT Data'!E2328*1000)/GDP!B25 -> 0.00018766556 | D25: =IF(C25>=0.00001,"Yes","No") -> Yes
A26: 2024 | B26: 2.1858216e+12 | C26: =('EM-DAT Data'!E2402*1000)/GDP!B26 -> 0.0034586536 | D26: =IF(C26>=0.00001,"Yes","No") -> Yes

Sheet GDP-keep
A1: =GDP!A1 -> Year | B1: =GDP!B1 -> GDP (current US$) | C1: Normalized Damage (xt) | D1: =GDP!D1 -> Keep
A2: =GDP!A2 -> 2000 | B2: =GDP!B2 -> 6.5544819e+11 | C2: =GDP!C2 -> 0 | D2: =GDP!D2 -> No
A3: =GDP!A3 -> 2001 | B3: =GDP!B3 -> 5.599837e+11 | C3: =GDP!C3 -> 8.0359481e-05 | D3: =GDP!D3 -> Yes
A4: =GDP!A4 -> 2002 | B4: =GDP!B4 -> 5.0979527e+11 | C4: =GDP!C4 -> 0 | D4: =GDP!D4 -> No
A5: =GDP!A5 -> 2003 | B5: =GDP!B5 -> 5.5823372e+11 | C5: =GDP!C5 -> 0.0005427834 | D5: =GDP!D5 -> Yes
A6: =GDP!A6 -> 2004 | B6: =GDP!B6 -> 6.6928932e+11 | C6: =GDP!C6 -> 5.528252e-07 | D6: =GDP!D6 -> No
A7: =GDP!A7 -> 2005 | B7: =GDP!B7 -> 8.9163383e+11 | C7: =GDP!C7 -> 0 | D7: =GDP!D7 -> No
A8: =GDP!A8 -> 2006 | B8: =GDP!B8 -> 1.1076267e+12 | C8: =GDP!C8 -> 0 | D8: =GDP!D8 -> No
A9: =GDP!A9 -> 2007 | B9: =GDP!B9 -> 1.3971142e+12 | C9: =GDP!C9 -> 8.9470135e-05 | D9: =GDP!D9 -> Yes
A10: =GDP!A10 -> 2008 | B10: =GDP!B10 -> 1.6958554e+12 | C10: =GDP!C10 -> 0.00065453694 | D10: =GDP!D10 -> Yes
A11: =GDP!A11 -> 2009 | B11: =GDP!B11 -> 1.6669963e+12 | C11: =GDP!C11 -> 0.00035992881 | D11: =GDP!D11 -> Yes
A12: =GDP!A12 -> 2010 | B12: =GDP!B12 -> 2.2088381e+12 | C12: =GDP!C12 -> 0.00036308682 | D12: =GDP!D12 -> Yes
A13: =GDP!A13 -> 2011 | B13: =GDP!B13 -> 2.6161566e+12 | C13: =GDP!C13 -> 0.00038300459 | D13: =GDP!D13 -> Yes
... A26: =GDP!A26 -> 2024 | B26: =GDP!B26 -> 2.1858216e+12 | C26: =GDP!C26 -> 0.0034586536 | D26: =GDP!D26 -> Yes

Sheet EM-DAT Info
A1: Source: | B1: EM-DAT, CRED / UCLouvain, Brussels, Belgium
B2: https://www.emdat.be
A3: Glossary: | B3: https://doc.emdat.be/docs/data-structure-and-content/emdat-public-table/
A4: Version: | B4: 2026-05-08
A5: File creation: | B5: Sat, 16 May 2026 17:15:52 UTC
A6: Table type: | B6: public_emdat_custom_request
A7: # of records: | B7: 2474

Sheet table 1
A1: Observation | B1: Year | C1: Normalised damage ratio (xt) | D1: Damage as % of annual GDP | E1: Retained
A2: 1 | B2: 2001 | C2: 8.03595e-05 | D2: 8e-05 | E2: Yes
A3: 2 | B3: 2003 | C3: 0.0005427834 | D3: 0.000543 | E3: Yes
A4: 3 | B4: 2007 | C4: 8.94701e-05 | D4: 8.9e-05 | E4: Yes
A5: 4 | B5: 2008 | C5: 0.0006545369 | D5: 0.000655 | E5: Yes
A6: 5 | B6: 2009 | C6: 0.0003599288 | D6: 0.00036 | E6: Yes
A7: 6 | B7: 2010 | C7: 0.0003630868 | D7: 0.000363 | E7: Yes
A8: 7 | B8: 2011 | C8: 0.0003830046 | D8: 0.000383 | E8: Yes
A9: 8 | B9: 2012 | C9: 6.93648e-05 | D9: 6.9e-05 | E9: Yes
A10: 9 | B10: 2013 | C10: 0.0002205984 | D10: 0.000221 | E10: Yes
A11: 10 | B11: 2014 | C11: 8.14318e-05 | D11: 8.1e-05 | E11: Yes
A12: 11 | B12: 2016 | C12: 0.0001113776 | D12: 0.000111 | E12: Yes
A13: 12 | B13: 2017 | C13: 4.8461e-05 | D13: 4.8e-05 | E13: Yes
... A19: 18 | B19: 2024 | C19: 0.0034586536 | D19: 0.003459 | E19: Yes
